<?xml version="1.0" encoding="utf-8"?>
<!-- This URDF was automatically created by SolidWorks to URDF Exporter! Originally created by Stephen Brawner (brawner@gmail.com) 
     Commit Version: 1.6.0-4-g7f85cfe  Build Version: 1.6.7995.38578
     For more information, please see http://wiki.ros.org/sw_urdf_exporter -->
<robot
  name="Assem1">
  <link
    name="base_link">
    <inertial>
      <origin
        xyz="0.00170644441190401 -0.00010951248939392 0.020137507133009"
        rpy="0 0 0" />
      <mass
        value="0.287718433342603" />
      <inertia
        ixx="0.00043625048274275"
        ixy="-1.0528143175783E-05"
        ixz="-6.62216645028294E-11"
        iyy="0.000552638256745813"
        iyz="-4.76560246682176E-11"
        izz="0.000733037492748617" />
    </inertial>
    <visual>
      <origin
        xyz="0 0 0"
        rpy="0 0 0" />
      <geometry>
        <mesh
          filename="package://Assem1/meshes/base_link.STL" />
      </geometry>
      <material
        name="">
        <color
          rgba="0.0196078431372549 0.0196078431372549 0.0196078431372549 1" />
      </material>
    </visual>
    <collision>
      <origin
        xyz="0 0 0"
        rpy="0 0 0" />
      <geometry>
        <mesh
          filename="package://Assem1/meshes/base_link.STL" />
      </geometry>
    </collision>
  </link>
  <link
    name="B_prop1_Link">
    <inertial>
      <origin
        xyz="7.31459151581682E-07 -2.01874710653582E-06 -0.00617262757614656"
        rpy="0 0 0" />
      <mass
        value="0.00470560400208223" />
      <inertia
        ixx="1.85522428966344E-05"
        ixy="7.79017193825592E-06"
        ixz="-3.58835413480609E-12"
        iyy="3.4554203858861E-06"
        iyz="1.3959908485915E-11"
        izz="2.19436691246909E-05" />
    </inertial>
    <visual>
      <origin
        xyz="0 0 0"
        rpy="0 0 0" />
      <geometry>
        <mesh
          filename="package://Assem1/meshes/B_prop1_Link.STL" />
      </geometry>
      <material
        name="">
        <color
          rgba="0.627450980392157 0.627450980392157 0.627450980392157 1" />
      </material>
    </visual>
    <collision>
      <origin
        xyz="0 0 0"
        rpy="0 0 0" />
      <geometry>
        <mesh
          filename="package://Assem1/meshes/B_prop1_Link.STL" />
      </geometry>
    </collision>
  </link>
  <joint
    name="Blue_prop1"
    type="continuous">
    <origin
      xyz="-0.17257 0.14811 -0.052109"
      rpy="-0.094849 -0.044451 0.43793" />
    <parent
      link="base_link" />
    <child
      link="B_prop1_Link" />
    <axis
      xyz="0 0 1" />
    <limit
      lower="-3.14"
      upper="3.14"
      effort="10"
      velocity="900" />
    <dynamics
      damping="0.001"
      friction="0.001" />
  </joint>
  <link
    name="B_prop2_Link">
    <inertial>
      <origin
        xyz="1.83252260643751E-07 -1.98326826152118E-06 -0.00617266232573843"
        rpy="0 0 0" />
      <mass
        value="0.00470560155567302" />
      <inertia
        ixx="2.16079875173634E-05"
        ixy="2.28377794244799E-06"
        ixz="-1.19218056547997E-12"
        iyy="3.9960494981713E-07"
        iyz="4.46537996457783E-12"
        izz="2.19435983745731E-05" />
    </inertial>
    <visual>
      <origin
        xyz="0 0 0"
        rpy="0 0 0" />
      <geometry>
        <mesh
          filename="package://Assem1/meshes/B_prop2_Link.STL" />
      </geometry>
      <material
        name="">
        <color
          rgba="0.627450980392157 0.627450980392157 0.627450980392157 1" />
      </material>
    </visual>
    <collision>
      <origin
        xyz="0 0 0"
        rpy="0 0 0" />
      <geometry>
        <mesh
          filename="package://Assem1/meshes/B_prop2_Link.STL" />
      </geometry>
    </collision>
  </link>
  <joint
    name="Blue_prop2"
    type="continuous">
    <origin
      xyz="-0.1434 -0.17706 -0.051992"
      rpy="0.015067 -0.10363 0.73026" />
    <parent
      link="base_link" />
    <child
      link="B_prop2_Link" />
    <axis
      xyz="0 0 1" />
    <limit
      lower="-3.14"
      upper="3.14"
      effort="10"
      velocity="900" />
    <dynamics
      damping="0.01"
      friction="0.01" />
  </joint>
  <link
    name="W_prop3_Link">
    <inertial>
      <origin
        xyz="-1.28649024433436E-07 -2.19146189972541E-07 -0.00617277347433426"
        rpy="0 0 0" />
      <mass
        value="0.00470544867986301" />
      <inertia
        ixx="2.16068682565638E-05"
        ixy="2.28259903929045E-06"
        ixz="2.48950874223512E-12"
        iyy="3.99361389385897E-07"
        iyz="4.7092728291607E-12"
        izz="2.19422332847507E-05" />
    </inertial>
    <visual>
      <origin
        xyz="0 0 0"
        rpy="0 0 0" />
      <geometry>
        <mesh
          filename="package://Assem1/meshes/W_prop3_Link.STL" />
      </geometry>
      <material
        name="">
        <color
          rgba="0.627450980392157 0.627450980392157 0.627450980392157 1" />
      </material>
    </visual>
    <collision>
      <origin
        xyz="0 0 0"
        rpy="0 0 0" />
      <geometry>
        <mesh
          filename="package://Assem1/meshes/W_prop3_Link.STL" />
      </geometry>
    </collision>
  </link>
  <joint
    name="White_prop3"
    type="continuous">
    <origin
      xyz="0.1819 -0.14798 -0.050454"
      rpy="0.10376 0.014184 0.73953" />
    <parent
      link="base_link" />
    <child
      link="W_prop3_Link" />
    <axis
      xyz="0 0 1" />
    <limit
      lower="-3.14"
      upper="3.14"
      effort="10"
      velocity="900" />
    <dynamics
      damping="0.01"
      friction="0.01" />
  </joint>
  <link
    name="W_prop4_Link">
    <inertial>
      <origin
        xyz="-1.90927498158744E-07 -3.74112121726E-07 -0.00617235089568641"
        rpy="0 0 0" />
      <mass
        value="0.00470577490170128" />
      <inertia
        ixx="2.15662250214858E-05"
        ixy="2.47775284354927E-06"
        ixz="6.35312790556522E-12"
        iyy="4.43219552098724E-07"
        iyz="2.35523113706649E-11"
        izz="2.19454547031465E-05" />
    </inertial>
    <visual>
      <origin
        xyz="0 0 0"
        rpy="0 0 0" />
      <geometry>
        <mesh
          filename="package://Assem1/meshes/W_prop4_Link.STL" />
      </geometry>
      <material
        name="">
        <color
          rgba="0.627450980392157 0.627450980392157 0.627450980392157 1" />
      </material>
    </visual>
    <collision>
      <origin
        xyz="0 0 0"
        rpy="0 0 0" />
      <geometry>
        <mesh
          filename="package://Assem1/meshes/W_prop4_Link.STL" />
      </geometry>
    </collision>
  </link>
  <joint
    name="White_prop4"
    type="continuous">
    <origin
      xyz="0.15258 0.17729 -0.052087"
      rpy="-0.015288 0.1036 0.72812" />
    <parent
      link="base_link" />
    <child
      link="W_prop4_Link" />
    <axis
      xyz="0 0 1" />
    <limit
      lower="-3.14"
      upper="3.14"
      effort="10"
      velocity="900" />
    <dynamics
      damping="0.01"
      friction="0.01" />
  </joint>
</robot>